Workbook
Name Slicer_Diabetes_Status: #N/A
Name Slicer_Weight_Status: #N/A

Sheet Customer Names
A1: Customer ID | B1: name | C1: First Name | D1: Title | E1: Last Name
A2: Id1 | B2: Hawks, Ms. Kelly | C2: Hawks | D2: Ms | E2: Kelly
A3: Id2 | B3: Lehner, Mr. Matthew D | C3: Lehner | D3: Mr | E3: Matthew D
A4: Id3 | B4: Lu, Mr. Phil | C4: Lu | D4: Mr | E4: Phil
A5: Id4 | B5: Osborne, Ms. Kelsey | C5: Osborne | D5: Ms | E5: Kelsey
A6: Id5 | B6: Kadala, Ms. Kristyn | C6: Kadala | D6: Ms | E6: Kristyn
A7: Id6 | B7: Baker, Mr. Russell B. | C7: Baker | D7: Mr | E7: Russell B
A8: Id7 | B8: Macpherson, Mr. Scott | C8: Macpherson | D8: Mr | E8: Scott
A9: Id8 | B9: Hallman, Mr. Stephen | C9: Hallman | D9: Mr | E9: Stephen
A10: Id9 | B10: Moran, Mr. Patrick R. | C10: Moran | D10: Mr | E10: Patrick R
A11: Id10 | B11: Benner, Ms. Brooke N. | C11: Benner | D11: Ms | E11: Brooke N
A12: Id11 | B12: Fierro Vargas, Ms. Paola Andrea | C12: Fierro Vargas | D12: Ms | E12: Paola Andrea
... A72: Id71 | B72: Turner, Mr. Jeff | C72: Turner | D72: Mr | E72: Jeff
A73: Id72 | B73: Rangel, Mr. Elenilton V. Sr. | C73: Rangel | D73: Mr | E73: Elenilton V | F73: Sr
A74: Id73 | B74: Lacey, Ms. Maurya | C74: Lacey | D74: Ms | E74: Maurya
A75: Id74 | B75: Stiger, Ms. Samantha C | C75: Stiger | D75: Ms | E75: Samantha C
A76: Id75 | B76: Caldwell, Ms. Bethany A | C76: Caldwell | D76: Ms | E76: Bethany A
A77: Id76 | B77: Marmillod, Mr. Yves | C77: Marmillod | D77: Mr | E77: Yves
A78: Id77 | B78: Cloutier-Simons, Ms. Danielle | C78: Cloutier-Simons | D78: Ms | E78: Danielle
A79: Id78 | B79: Vegas, Ms. Julia | C79: Vegas | D79: Ms | E79: Julia
A80: Id79 | B80: Cochran, Mr. Joshua | C80: Cochran | D80: Mr | E80: Joshua
A81: Id80 | B81: Holtzapple, Ms. Jennifer | C81: Holtzapple | D81: Ms | E81: Jennifer
A82: Id81 | B82: Meyer, Ms. Gwen M. | C82: Meyer | D82: Ms | E82: Gwen M
A83: Id82 | B83: Brickley, Mr. Patrick | C83: Brickley | D83: Mr | E83: Patrick
A84: Id83 | B84: Magee, Ms. Kate | C84: Magee | D84: Ms | E84: Kate
A85: Id84 | B85: Thoma, Mr. Kevin | C85: Thoma | D85: Mr | E85: Kevin
... A188: Id187 | B188: Dublin, Mr. Andrew P | C188: Dublin | D188: Mr | E188: Andrew P
A189: Id188 | B189: Cleland, Mr. George M. V | C189: Cleland | D189: Mr | E189: George M | F189: V
A190: Id189 | B190: Evans, Ms. Sarah | C190: Evans | D190: Ms | E190: Sarah
A191: Id190 | B191: Boyd, Ms. Lara | C191: Boyd | D191: Ms | E191: Lara
A192: Id191 | B192: Roulier, Mr. Sebastien | C192: Roulier | D192: Mr | E192: Sebastien
A193: Id192 | B193: Mullins, Mr. Padraig | C193: Mullins | D193: Mr | E193: Padraig
A194: Id193 | B194: Hofmann, Ms. Heather | C194: Hofmann | D194: Ms | E194: Heather
A195: Id194 | B195: Garcia Garcia, Mr. Jorge | C195: Garcia Garcia | D195: Mr | E195: Jorge
A196: Id195 | B196: Klecker, Mr. Jack R | C196: Klecker | D196: Mr | E196: Jack R
A197: Id196 | B197: Cancre, Mr. Felix | C197: Cancre | D197: Mr | E197: Felix
A198: Id197 | B198: Denucci, Mr. Christopher C | C198: Denucci | D198: Mr | E198: Christopher C
A199: Id198 | B199: Saldana, Mr. Jesse | C199: Saldana | D199: Mr | E199: Jesse
A200: Id199 | B200: Weinberg, Ms. Jill | C200: Weinberg | D200: Ms | E200: Jill
A201: Id200 | B201: Walsh, Mr. William | C201: Walsh | D201: Mr | E201: William
...

Sheet Medical Examinations
A1: Customer ID | B1: BMI | C1: HBA1C | D1: CLEANED Heart Issues | E1: Heart Issues | F1: Any Transplants | G1: Cancer history | H1: CLEANED Number Of Major Surgeries | I1: NumberOfMajorSurgeries | J1: cleaned smoker | K1: cleaned smoker | L1: smoker | M1: COUNT OF BLANKS | N1: Weight Status | O1: Diabetes Status
A2: Id1 | B2: 47.41 | C2: 7.47 | D2: =PROPER(E:E) -> No | E2: No | F2: No | G2: No | H2: =IF(I2="No major surgery","0",I2) -> 0 | I2: No major surgery | J2: =PROPER(K2) -> Yes | K2: =IF(L2="?", "No", L2) -> yes | L2: yes | M2: =COUNTIF(A1:L2336,"?") -> 1076 | N2: {=_xlfn.IFS(B2<18.5,"Under Weight",B2<=24.99,"Normal Weight",B2<=29.99,"Over Weight",B2>=30,"Obesity")} -> Obesity | O2: {=_xlfn.IFS(C2<5.7,"Normal",C2<=6.49,"Prediabetes",C2>=6.5,"Diabetes")} -> Diabetes
A3: Id2 | B3: 30.36 | C3: 5.77 | D3: =PROPER(E:E) -> No | E3: No | F3: No | G3: No | H3: =IF(I3="No major surgery","0",I3) -> 0 | I3: No major surgery | J3: =PROPER(K3) -> Yes | K3: =IF(L3="?", "No", L3) -> yes | L3: yes | N3: {=_xlfn.IFS(B3<18.5,"Under Weight",B3<=24.99,"Normal Weight",B3<=29.99,"Over Weight",B3>=30,"Obesity")} -> Obesity | O3: {=_xlfn.IFS(C3<5.7,"Normal",C3<=6.49,"Prediabetes",C3>=6.5,"Diabetes")} -> Prediabetes
A4: Id3 | B4: 34.485 | C4: 11.87 | D4: =PROPER(E:E) -> Yes | E4: yes | F4: No | G4: No | H4: =IF(I4="No major surgery","0",I4) -> 2 | I4: 2 | J4: =PROPER(K4) -> Yes | K4: =IF(L4="?", "No", L4) -> yes | L4: yes | N4: {=_xlfn.IFS(B4<18.5,"Under Weight",B4<=24.99,"Normal Weight",B4<=29.99,"Over Weight",B4>=30,"Obesity")} -> Obesity | O4: {=_xlfn.IFS(C4<5.7,"Normal",C4<=6.49,"Prediabetes",C4>=6.5,"Diabetes")} -> Diabetes
A5: Id4 | B5: 38.095 | C5: 6.05 | D5: =PROPER(E:E) -> No | E5: No | F5: No | G5: No | H5: =IF(I5="No major surgery","0",I5) -> 0 | I5: No major surgery | J5: =PROPER(K5) -> Yes | K5: =IF(L5="?", "No", L5) -> yes | L5: yes | N5: {=_xlfn.IFS(B5<18.5,"Under Weight",B5<=24.99,"Normal Weight",B5<=29.99,"Over Weight",B5>=30,"Obesity")} -> Obesity | O5: {=_xlfn.IFS(C5<5.7,"Normal",C5<=6.49,"Prediabetes",C5>=6.5,"Diabetes")} -> Prediabetes
A6: Id5 | B6: 35.53 | C6: 5.45 | D6: =PROPER(E:E) -> No | E6: No | F6: No | G6: No | H6: =IF(I6="No major surgery","0",I6) -> 0 | I6: No major surgery | J6: =PROPER(K6) -> Yes | K6: =IF(L6="?", "No", L6) -> yes | L6: yes | N6: {=_xlfn.IFS(B6<18.5,"Under Weight",B6<=24.99,"Normal Weight",B6<=29.99,"Over Weight",B6>=30,"Obesity")} -> Obesity | O6: {=_xlfn.IFS(C6<5.7,"Normal",C6<=6.49,"Prediabetes",C6>=6.5,"Diabetes")} -> Normal
A7: Id6 | B7: 32.8 | C7: 6.59 | D7: =PROPER(E:E) -> No | E7: No | F7: No | G7: No | H7: =IF(I7="No major surgery","0",I7) -> 0 | I7: No major surgery | J7: =PROPER(K7) -> Yes | K7: =IF(L7="?", "No", L7) -> yes | L7: yes | N7: {=_xlfn.IFS(B7<18.5,"Under Weight",B7<=24.99,"Normal Weight",B7<=29.99,"Over Weight",B7>=30,"Obesity")} -> Obesity | O7: {=_xlfn.IFS(C7<5.7,"Normal",C7<=6.49,"Prediabetes",C7>=6.5,"Diabetes")} -> Diabetes
A8: Id7 | B8: 36.4 | C8: 6.07 | D8: =PROPER(E:E) -> No | E8: No | F8: No | G8: No | H8: =IF(I8="No major surgery","0",I8) -> 0 | I8: No major surgery | J8: =PROPER(K8) -> Yes | K8: =IF(L8="?", "No", L8) -> yes | L8: yes | N8: {=_xlfn.IFS(B8<18.5,"Under Weight",B8<=24.99,"Normal Weight",B8<=29.99,"Over Weight",B8>=30,"Obesity")} -> Obesity | O8: {=_xlfn.IFS(C8<5.7,"Normal",C8<=6.49,"Prediabetes",C8>=6.5,"Diabetes")} -> Prediabetes
A9: Id8 | B9: 36.96 | C9: 7.93 | D9: =PROPER(E:E) -> No | E9: No | F9: No | G9: No | H9: =IF(I9="No major surgery","0",I9) -> 3 | I9: 3 | J9: =PROPER(K9) -> Yes | K9: =IF(L9="?", "No", L9) -> yes | L9: yes | N9: {=_xlfn.IFS(B9<18.5,"Under Weight",B9<=24.99,"Normal Weight",B9<=29.99,"Over Weight",B9>=30,"Obesity")} -> Obesity | O9: {=_xlfn.IFS(C9<5.7,"Normal",C9<=6.49,"Prediabetes",C9>=6.5,"Diabetes")} -> Diabetes
A10: Id9 | B10: 41.14 | C10: 9.58 | D10: =PROPER(E:E) -> Yes | E10: yes | F10: No | G10: Yes | H10: =IF(I10="No major surgery","0",I10) -> 1 | I10: 1 | J10: =PROPER(K10) -> Yes | K10: =IF(L10="?", "No", L10) -> yes | L10: yes | N10: {=_xlfn.IFS(B10<18.5,"Under Weight",B10<=24.99,"Normal Weight",B10<=29.99,"Over Weight",B10>=30,"Obesity")} -> Obesity | O10: {=_xlfn.IFS(C10<5.7,"Normal",C10<=6.49,"Prediabetes",C10>=6.5,"Diabetes")} -> Diabetes
A11: Id10 | B11: 38.06 | C11: 10.79 | D11: =PROPER(E:E) -> No | E11: No | F11: No | G11: No | H11: =IF(I11="No major surgery","0",I11) -> 0 | I11: No major surgery | J11: =PROPER(K11) -> Yes | K11: =IF(L11="?", "No", L11) -> yes | L11: yes | N11: {=_xlfn.IFS(B11<18.5,"Under Weight",B11<=24.99,"Normal Weight",B11<=29.99,"Over Weight",B11>=30,"Obesity")} -> Obesity | O11: {=_xlfn.IFS(C11<5.7,"Normal",C11<=6.49,"Prediabetes",C11>=6.5,"Diabetes")} -> Diabetes
A12: Id11 | B12: 37.7 | C12: 5.96 | D12: =PROPER(E:E) -> Yes | E12: yes | F12: No | G12: No | H12: =IF(I12="No major surgery","0",I12) -> 2 | I12: 2 | J12: =PROPER(K12) -> Yes | K12: =IF(L12="?", "No", L12) -> yes | L12: yes | N12: {=_xlfn.IFS(B12<18.5,"Under Weight",B12<=24.99,"Normal Weight",B12<=29.99,"Over Weight",B12>=30,"Obesity")} -> Obesity | O12: {=_xlfn.IFS(C12<5.7,"Normal",C12<=6.49,"Prediabetes",C12>=6.5,"Diabetes")} -> Prediabetes
A13: Id12 | B13: 42.13 | C13: 11.9 | D13: =PROPER(E:E) -> No | E13: No | F13: No | G13: No | H13: =IF(I13="No major surgery","0",I13) -> 0 | I13: No major surgery | J13: =PROPER(K13) -> Yes | K13: =IF(L13="?", "No", L13) -> yes | L13: yes | N13: {=_xlfn.IFS(B13<18.5,"Under Weight",B13<=24.99,"Normal Weight",B13<=29.99,"Over Weight",B13>=30,"Obesity")} -> Obesity | O13: {=_xlfn.IFS(C13<5.7,"Normal",C13<=6.49,"Prediabetes",C13>=6.5,"Diabetes")} -> Diabetes
A14: Id13 | B14: 40.92 | C14: 8.41 | D14: =PROPER(E:E) -> No | E14: No | F14: No | G14: No | H14: =IF(I14="No major surgery","0",I14) -> 0 | I14: No major surgery | J14: =PROPER(K14) -> Yes | K14: =IF(L14="?", "No", L14) -> yes | L14: yes | N14: {=_xlfn.IFS(B14<18.5,"Under Weight",B14<=24.99,"Normal Weight",B14<=29.99,"Over Weight",B14>=30,"Obesity")} -> Obesity | O14: {=_xlfn.IFS(C14<5.7,"Normal",C14<=6.49,"Prediabetes",C14>=6.5,"Diabetes")} -> Diabetes
A15: Id14 | B15: 40.565 | C15: 7.02 | D15: =PROPER(E:E) -> No | E15: No | F15: No | G15: No | H15: =IF(I15="No major surgery","0",I15) -> 0 | I15: No major surgery | J15: =PROPER(K15) -> Yes | K15: =IF(L15="?", "No", L15) -> yes | L15: yes | N15: {=_xlfn.IFS(B15<18.5,"Under Weight",B15<=24.99,"Normal Weight",B15<=29.99,"Over Weight",B15>=30,"Obesity")} -> Obesity | O15: {=_xlfn.IFS(C15<5.7,"Normal",C15<=6.49,"Prediabetes",C15>=6.5,"Diabetes")} -> Diabetes
A16: Id15 | B16: 36.385 | C16: 7.59 | D16: =PROPER(E:E) -> Yes | E16: yes | F16: No | G16: No | H16: =IF(I16="No major surgery","0",I16) -> 2 | I16: 2 | J16: =PROPER(K16) -> Yes | K16: =IF(L16="?", "No", L16) -> yes | L16: yes | N16: {=_xlfn.IFS(B16<18.5,"Under Weight",B16<=24.99,"Normal Weight",B16<=29.99,"Over Weight",B16>=30,"Obesity")} -> Obesity | O16: {=_xlfn.IFS(C16<5.7,"Normal",C16<=6.49,"Prediabetes",C16>=6.5,"Diabetes")} -> Diabetes
A17: Id16 | B17: 39.9 | C17: 11.32 | D17: =PROPER(E:E) -> No | E17: No | F17: No | G17: No | H17: =IF(I17="No major surgery","0",I17) -> 0 | I17: No major surgery | J17: =PROPER(K17) -> Yes | K17: =IF(L17="?", "No", L17) -> yes | L17: yes | N17: {=_xlfn.IFS(B17<18.5,"Under Weight",B17<=24.99,"Normal Weight",B17<=29.99,"Over Weight",B17>=30,"Obesity")} -> Obesity | O17: {=_xlfn.IFS(C17<5.7,"Normal",C17<=6.49,"Prediabetes",C17>=6.5,"Diabetes")} -> Diabetes
A18: Id17 | B18: 33.8 | C18: 7.67 | D18: =PROPER(E:E) -> No | E18: No | F18: No | G18: No | H18: =IF(I18="No major surgery","0",I18) -> 3 | I18: 3 | J18: =PROPER(K18) -> Yes | K18: =IF(L18="?", "No", L18) -> yes | L18: yes | N18: {=_xlfn.IFS(B18<18.5,"Under Weight",B18<=24.99,"Normal Weight",B18<=29.99,"Over Weight",B18>=30,"Obesity")} -> Obesity | O18: {=_xlfn.IFS(C18<5.7,"Normal",C18<=6.49,"Prediabetes",C18>=6.5,"Diabetes")} -> Diabetes
A19: Id18 | B19: 36.765 | C19: 7.29 | D19: =PROPER(E:E) -> Yes | E19: yes | F19: No | G19: Yes | H19: =IF(I19="No major surgery","0",I19) -> 1 | I19: 1 | J19: =PROPER(K19) -> Yes | K19: =IF(L19="?", "No", L19) -> yes | L19: yes | N19: {=_xlfn.IFS(B19<18.5,"Under Weight",B19<=24.99,"Normal Weight",B19<=29.99,"Over Weight",B19>=30,"Obesity")} -> Obesity | O19: {=_xlfn.IFS(C19<5.7,"Normal",C19<=6.49,"Prediabetes",C19>=6.5,"Diabetes")} -> Diabetes
A20: Id19 | B20: 36.955 | C20: 4.72 | D20: =PROPER(E:E) -> Yes | E20: yes | F20: No | G20: No | H20: =IF(I20="No major surgery","0",I20) -> 1 | I20: 1 | J20: =PROPER(K20) -> Yes | K20: =IF(L20="?", "No", L20) -> yes | L20: yes | N20: {=_xlfn.IFS(B20<18.5,"Under Weight",B20<=24.99,"Normal Weight",B20<=29.99,"Over Weight",B20>=30,"Obesity")} -> Obesity | O20: {=_xlfn.IFS(C20<5.7,"Normal",C20<=6.49,"Prediabetes",C20>=6.5,"Diabetes")} -> Normal
A21: Id20 | B21: 42.9 | C21: 11.41 | D21: =PROPER(E:E) -> No | E21: No | F21: No | G21: No | H21: =IF(I21="No major surgery","0",I21) -> 0 | I21: No major surgery | J21: =PROPER(K21) -> Yes | K21: =IF(L21="?", "No", L21) -> yes | L21: yes | N21: {=_xlfn.IFS(B21<18.5,"Under Weight",B21<=24.99,"Normal Weight",B21<=29.99,"Over Weight",B21>=30,"Obesity")} -> Obesity | O21: {=_xlfn.IFS(C21<5.7,"Normal",C21<=6.49,"Prediabetes",C21>=6.5,"Diabetes")} -> Diabetes
A22: Id21 | B22: 36.3 | C22: 11.5 | D22: =PROPER(E:E) -> Yes | E22: yes | F22: No | G22: No | H22: =IF(I22="No major surgery","0",I22) -> 2 | I22: 2 | J22: =PROPER(K22) -> Yes | K22: =IF(L22="?", "No", L22) -> yes | L22: yes | N22: {=_xlfn.IFS(B22<18.5,"Under Weight",B22<=24.99,"Normal Weight",B22<=29.99,"Over Weight",B22>=30,"Obesity")} -> Obesity | O22: {=_xlfn.IFS(C22<5.7,"Normal",C22<=6.49,"Prediabetes",C22>=6.5,"Diabetes")} -> Diabetes
A23: Id22 | B23: 32.2 | C23: 6.22 | D23: =PROPER(E:E) -> Yes | E23: yes | F23: No | G23: No | H23: =IF(I23="No major surgery","0",I23) -> 2 | I23: 2 | J23: =PROPER(K23) -> Yes | K23: =IF(L23="?", "No", L23) -> yes | L23: yes | N23: {=_xlfn.IFS(B23<18.5,"Under Weight",B23<=24.99,"Normal Weight",B23<=29.99,"Over Weight",B23>=30,"Obesity")} -> Obesity | O23: {=_xlfn.IFS(C23<5.7,"Normal",C23<=6.49,"Prediabetes",C23>=6.5,"Diabetes")} -> Prediabetes
A24: Id23 | B24: 31.3 | C24: 11.38 | D24: =PROPER(E:E) -> No | E24: No | F24: No | G24: No | H24: =IF(I24="No major surgery","0",I24) -> 3 | I24: 3 | J24: =PROPER(K24) -> Yes | K24: =IF(L24="?", "No", L24) -> yes | L24: yes | N24: {=_xlfn.IFS(B24<18.5,"Under Weight",B24<=24.99,"Normal Weight",B24<=29.99,"Over Weight",B24>=30,"Obesity")} -> Obesity | O24: {=_xlfn.IFS(C24<5.7,"Normal",C24<=6.49,"Prediabetes",C24>=6.5,"Diabetes")} -> Diabetes
A25: Id24 | B25: 41.8 | C25: 7.89 | D25: =PROPER(E:E) -> Yes | E25: yes | F25: No | G25: No | H25: =IF(I25="No major surgery","0",I25) -> 2 | I25: 2 | J25: =PROPER(K25) -> Yes | K25: =IF(L25="?", "No", L25) -> yes | L25: yes | N25: {=_xlfn.IFS(B25<18.5,"Under Weight",B25<=24.99,"Normal Weight",B25<=29.99,"Over Weight",B25>=30,"Obesity")} -> Obesity | O25: {=_xlfn.IFS(C25<5.7,"Normal",C25<=6.49,"Prediabetes",C25>=6.5,"Diabetes")} -> Diabetes
A26: Id25 | B26: 35.09 | C26: 4.38 | D26: =PROPER(E:E) -> Yes | E26: yes | F26: No | G26: No | H26: =IF(I26="No major surgery","0",I26) -> 2 | I26: 2 | J26: =PROPER(K26) -> Yes | K26: =IF(L26="?", "No", L26) -> yes | L26: yes | N26: {=_xlfn.IFS(B26<18.5,"Under Weight",B26<=24.99,"Normal Weight",B26<=29.99,"Over Weight",B26>=30,"Obesity")} -> Obesity | O26: {=_xlfn.IFS(C26<5.7,"Normal",C26<=6.49,"Prediabetes",C26>=6.5,"Diabetes")} -> Normal
A27: Id26 | B27: 33.88 | C27: 7.01 | D27: =PROPER(E:E) -> No | E27: No | F27: No | G27: No | H27: =IF(I27="No major surgery","0",I27) -> 3 | I27: 3 | J27: =PROPER(K27) -> Yes | K27: =IF(L27="?", "No", L27) -> yes | L27: yes | N27: {=_xlfn.IFS(B27<18.5,"Under Weight",B27<=24.99,"Normal Weight",B27<=29.99,"Over Weight",B27>=30,"Obesity")} -> Obesity | O27: {=_xlfn.IFS(C27<5.7,"Normal",C27<=6.49,"Prediabetes",C27>=6.5,"Diabetes")} -> Diabetes
A28: Id27 | B28: 30.875 | C28: 11.88 | D28: =PROPER(E:E) -> No | E28: No | F28: No | G28: No | H28: =IF(I28="No major surgery","0",I28) -> 0 | I28: No major surgery | J28: =PROPER(K28) -> Yes | K28: =IF(L28="?", "No", L28) -> yes | L28: yes | N28: {=_xlfn.IFS(B28<18.5,"Under Weight",B28<=24.99,"Normal Weight",B28<=29.99,"Over Weight",B28>=30,"Obesity")} -> Obesity | O28: {=_xlfn.IFS(C28<5.7,"Normal",C28<=6.49,"Prediabetes",C28>=6.5,"Diabetes")} -> Diabetes
A29: Id28 | B29: 36.86 | C29: 5.19 | D29: =PROPER(E:E) -> Yes | E29: yes | F29: No | G29: Yes | H29: =IF(I29="No major surgery","0",I29) -> 1 | I29: 1 | J29: =PROPER(K29) -> Yes | K29: =IF(L29="?", "No", L29) -> yes | L29: yes | N29: {=_xlfn.IFS(B29<18.5,"Under Weight",B29<=24.99,"Normal Weight",B29<=29.99,"Over Weight",B29>=30,"Obesity")} -> Obesity | O29: {=_xlfn.IFS(C29<5.7,"Normal",C29<=6.49,"Prediabetes",C29>=6.5,"Diabetes")} -> Normal
A30: Id29 | B30: 35.86 | C30: 6.74 | D30: =PROPER(E:E) -> Yes | E30: yes | F30: No | G30: No | H30: =IF(I30="No major surgery","0",I30) -> 2 | I30: 2 | J30: =PROPER(K30) -> Yes | K30: =IF(L30="?", "No", L30) -> yes | L30: yes | N30: {=_xlfn.IFS(B30<18.5,"Under Weight",B30<=24.99,"Normal Weight",B30<=29.99,"Over Weight",B30>=30,"Obesity")} -> Obesity | O30: {=_xlfn.IFS(C30<5.7,"Normal",C30<=6.49,"Prediabetes",C30>=6.5,"Diabetes")} -> Diabetes
A31: Id30 | B31: 37.05 | C31: 8.44 | D31: =PROPER(E:E) -> No | E31: No | F31: No | G31: No | H31: =IF(I31="No major surgery","0",I31) -> 0 | I31: No major surgery | J31: =PROPER(K31) -> Yes | K31: =IF(L31="?", "No", L31) -> yes | L31: yes | N31: {=_xlfn.IFS(B31<18.5,"Under Weight",B31<=24.99,"Normal Weight",B31<=29.99,"Over Weight",B31>=30,"Obesity")} -> Obesity | O31: {=_xlfn.IFS(C31<5.7,"Normal",C31<=6.49,"Prediabetes",C31>=6.5,"Diabetes")} -> Diabetes
A32: Id31 | B32: 43.89 | C32: 8.71 | D32: =PROPER(E:E) -> No | E32: No | F32: No | G32: No | H32: =IF(I32="No major surgery","0",I32) -> 0 | I32: No major surgery | J32: =PROPER(K32) -> Yes | K32: =IF(L32="?", "No", L32) -> yes | L32: yes | N32: {=_xlfn.IFS(B32<18.5,"Under Weight",B32<=24.99,"Normal Weight",B32<=29.99,"Over Weight",B32>=30,"Obesity")} -> Obesity | O32: {=_xlfn.IFS(C32<5.7,"Normal",C32<=6.49,"Prediabetes",C32>=6.5,"Diabetes")} -> Diabetes
A33: Id32 | B33: 42.35 | C33: 5.08 | D33: =PROPER(E:E) -> Yes | E33: yes | F33: No | G33: No | H33: =IF(I33="No major surgery","0",I33) -> 0 | I33: No major surgery | J33: =PROPER(K33) -> Yes | K33: =IF(L33="?", "No", L33) -> yes | L33: yes | N33: {=_xlfn.IFS(B33<18.5,"Under Weight",B33<=24.99,"Normal Weight",B33<=29.99,"Over Weight",B33>=30,"Obesity")} -> Obesity | O33: {=_xlfn.IFS(C33<5.7,"Normal",C33<=6.49,"Prediabetes",C33>=6.5,"Diabetes")} -> Normal
A34: Id33 | B34: 31.35 | C34: 6.86 | D34: =PROPER(E:E) -> No | E34: No | F34: No | G34: No | H34: =IF(I34="No major surgery","0",I34) -> 0 | I34: No major surgery | J34: =PROPER(K34) -> Yes | K34: =IF(L34="?", "No", L34) -> yes | L34: yes | N34: {=_xlfn.IFS(B34<18.5,"Under Weight",B34<=24.99,"Normal Weight",B34<=29.99,"Over Weight",B34>=30,"Obesity")} -> Obesity | O34: {=_xlfn.IFS(C34<5.7,"Normal",C34<=6.49,"Prediabetes",C34>=6.5,"Diabetes")} -> Diabetes
A35: Id34 | B35: 47.6 | C35: 5.95 | D35: =PROPER(E:E) -> Yes | E35: yes | F35: No | G35: No | H35: =IF(I35="No major surgery","0",I35) -> 0 | I35: No major surgery | J35: =PROPER(K35) -> Yes | K35: =IF(L35="?", "No", L35) -> yes | L35: yes | N35: {=_xlfn.IFS(B35<18.5,"Under Weight",B35<=24.99,"Normal Weight",B35<=29.99,"Over Weight",B35>=30,"Obesity")} -> Obesity | O35: {=_xlfn.IFS(C35<5.7,"Normal",C35<=6.49,"Prediabetes",C35>=6.5,"Diabetes")} -> Prediabetes
A36: Id35 | B36: 46.2 | C36: 6.09 | D36: =PROPER(E:E) -> No | E36: No | F36: No | G36: Yes | H36: =IF(I36="No major surgery","0",I36) -> 1 | I36: 1 | J36: =PROPER(K36) -> Yes | K36: =IF(L36="?", "No", L36) -> yes | L36: yes | N36: {=_xlfn.IFS(B36<18.5,"Under Weight",B36<=24.99,"Normal Weight",B36<=29.99,"Over Weight",B36>=30,"Obesity")} -> Obesity | O36: {=_xlfn.IFS(C36<5.7,"Normal",C36<=6.49,"Prediabetes",C36>=6.5,"Diabetes")} -> Prediabetes
A37: Id36 | B37: 32.015 | C37: 11.75 | D37: =PROPER(E:E) -> No | E37: No | F37: No | G37: No | H37: =IF(I37="No major surgery","0",I37) -> 0 | I37: No major surgery | J37: =PROPER(K37) -> Yes | K37: =IF(L37="?", "No", L37) -> yes | L37: yes | N37: {=_xlfn.IFS(B37<18.5,"Under Weight",B37<=24.99,"Normal Weight",B37<=29.99,"Over Weight",B37>=30,"Obesity")} -> Obesity | O37: {=_xlfn.IFS(C37<5.7,"Normal",C37<=6.49,"Prediabetes",C37>=6.5,"Diabetes")} -> Diabetes
A38: Id37 | B38: 40.565 | C38: 7.37 | D38: =PROPER(E:E) -> No | E38: No | F38: No | G38: No | H38: =IF(I38="No major surgery","0",I38) -> 0 | I38: No major surgery | J38: =PROPER(K38) -> Yes | K38: =IF(L38="?", "No", L38) -> yes | L38: yes | N38: {=_xlfn.IFS(B38<18.5,"Under Weight",B38<=24.99,"Normal Weight",B38<=29.99,"Over Weight",B38>=30,"Obesity")} -> Obesity | O38: {=_xlfn.IFS(C38<5.7,"Normal",C38<=6.49,"Prediabetes",C38>=6.5,"Diabetes")} -> Diabetes
A39: Id38 | B39: 32.45 | C39: 11.91 | D39: =PROPER(E:E) -> No | E39: No | F39: No | G39: No | H39: =IF(I39="No major surgery","0",I39) -> 0 | I39: No major surgery | J39: =PROPER(K39) -> Yes | K39: =IF(L39="?", "No", L39) -> yes | L39: yes | N39: {=_xlfn.IFS(B39<18.5,"Under Weight",B39<=24.99,"Normal Weight",B39<=29.99,"Over Weight",B39>=30,"Obesity")} -> Obesity | O39: {=_xlfn.IFS(C39<5.7,"Normal",C39<=6.49,"Prediabetes",C39>=6.5,"Diabetes")} -> Diabetes
A40: Id39 | B40: 34.96 | C40: 6.52 | D40: =PROPER(E:E) -> No | E40: No | F40: No | G40: No | H40: =IF(I40="No major surgery","0",I40) -> 0 | I40: No major surgery | J40: =PROPER(K40) -> Yes | K40: =IF(L40="?", "No", L40) -> yes | L40: yes | N40: {=_xlfn.IFS(B40<18.5,"Under Weight",B40<=24.99,"Normal Weight",B40<=29.99,"Over Weight",B40>=30,"Obesity")} -> Obesity | O40: {=_xlfn.IFS(C40<5.7,"Normal",C40<=6.49,"Prediabetes",C40>=6.5,"Diabetes")} -> Diabetes
...

Sheet Hospitalisation Details
A1: Customer ID | B1: corrected year | C1: year | D1: corrected month | E1: month | F1: date | G1: Date of Birth | H1: AGE | I1: children | J1: charges | K1: cleaned Hospital tier | L1: Hospital tier | M1: cleaned city tier | N1: City tier | O1: cleaned State ID | P1: State ID | Q1: COUNT OF BLANKS
A2: ? | B2: =SUBSTITUTE(C2,"?",ROUNDUP(AVERAGEIF(C:C,"<>~?",C:C),0)) -> 2004 | C2: 2004 | D2: =SUBSTITUTE(E2,"?","sep") -> Nov | E2: Nov | F2: 6 | G2: =CONCATENATE(F2,"-",D2,"-",B2) -> 6-Nov-2004 | H2: =DATEDIF(G2,DATE(2023,6,8),"Y") -> 18 | I2: 0 | J2: 1137.01 | K2: =IF(L2="?","tier - 2",L2) -> tier - 3 | L2: tier - 3 | M2: =IF(N2="?","tier - 1",N2) -> tier - 1 | N2: tier - 1 | O2: =IF(P2="?","UNKNOWN",P2) -> R1013 | P2: R1013
A3: ? | B3: =SUBSTITUTE(C3,"?",ROUNDUP(AVERAGEIF(C:C,"<>~?",C:C),0)) -> 1999 | C3: 1999 | D3: =SUBSTITUTE(E3,"?","sep") -> Jun | E3: Jun | F3: 9 | G3: =CONCATENATE(F3,"-",D3,"-",B3) -> 9-Jun-1999 | H3: =DATEDIF(G3,DATE(2023,6,8),"Y") -> 23 | I3: 1 | J3: 2775.19 | K3: =IF(L3="?","tier - 2",L3) -> tier - 2 | L3: tier - 2 | M3: =IF(N3="?","tier - 1",N3) -> tier - 1 | N3: tier - 1 | O3: =IF(P3="?","UNKNOWN",P3) -> R1012 | P3: R1012
A4: ? | B4: =SUBSTITUTE(C4,"?",ROUNDUP(AVERAGEIF(C:C,"<>~?",C:C),0)) -> 1985 | C4: 1985 | D4: =SUBSTITUTE(E4,"?","sep") -> Dec | E4: Dec | F4: 20 | G4: =CONCATENATE(F4,"-",D4,"-",B4) -> 20-Dec-1985 | H4: =DATEDIF(G4,DATE(2023,6,8),"Y") -> 37 | I4: 2 | J4: 6203.9 | K4: =IF(L4="?","tier - 2",L4) -> tier - 1 | L4: tier - 1 | M4: =IF(N4="?","tier - 1",N4) -> tier - 2 | N4: tier - 2 | O4: =IF(P4="?","UNKNOWN",P4) -> R1012 | P4: R1012
A5: ? | B5: =SUBSTITUTE(C5,"?",ROUNDUP(AVERAGEIF(C:C,"<>~?",C:C),0)) -> 2000 | C5: 2000 | D5: =SUBSTITUTE(E5,"?","sep") -> Oct | E5: Oct | F5: 13 | G5: =CONCATENATE(F5,"-",D5,"-",B5) -> 13-Oct-2000 | H5: =DATEDIF(G5,DATE(2023,6,8),"Y") -> 22 | I5: 0 | J5: 35585.58 | K5: =IF(L5="?","tier - 2",L5) -> tier - 1 | L5: tier - 1 | M5: =IF(N5="?","tier - 1",N5) -> tier - 2 | N5: tier - 2 | O5: =IF(P5="?","UNKNOWN",P5) -> R1011 | P5: R1011
A6: ? | B6: =SUBSTITUTE(C6,"?",ROUNDUP(AVERAGEIF(C:C,"<>~?",C:C),0)) -> 1992 | C6: 1992 | D6: =SUBSTITUTE(E6,"?","sep") -> Oct | E6: Oct | F6: 6 | G6: =CONCATENATE(F6,"-",D6,"-",B6) -> 6-Oct-1992 | H6: =DATEDIF(G6,DATE(2023,6,8),"Y") -> 30 | I6: 0 | J6: 36837.47 | K6: =IF(L6="?","tier - 2",L6) -> tier - 1 | L6: tier - 1 | M6: =IF(N6="?","tier - 1",N6) -> tier - 2 | N6: tier - 2 | O6: =IF(P6="?","UNKNOWN",P6) -> R1011 | P6: R1011
A7: ? | B7: =SUBSTITUTE(C7,"?",ROUNDUP(AVERAGEIF(C:C,"<>~?",C:C),0)) -> 1991 | C7: 1991 | D7: =SUBSTITUTE(E7,"?","sep") -> Nov | E7: Nov | F7: 22 | G7: =CONCATENATE(F7,"-",D7,"-",B7) -> 22-Nov-1991 | H7: =DATEDIF(G7,DATE(2023,6,8),"Y") -> 31 | I7: 2 | J7: 38711 | K7: =IF(L7="?","tier - 2",L7) -> tier - 1 | L7: tier - 1 | M7: =IF(N7="?","tier - 1",N7) -> tier - 3 | N7: tier - 3 | O7: =IF(P7="?","UNKNOWN",P7) -> R1011 | P7: R1011
A8: Id1 | B8: =SUBSTITUTE(C8,"?",ROUNDUP(AVERAGEIF(C:C,"<>~?",C:C),0)) -> 1968 | C8: 1968 | D8: =SUBSTITUTE(E8,"?","sep") -> Oct | E8: Oct | F8: 12 | G8: =CONCATENATE(F8,"-",D8,"-",B8) -> 12-Oct-1968 | H8: =DATEDIF(G8,DATE(2023,6,8),"Y") -> 54 | I8: 0 | J8: 63770.43 | K8: =IF(L8="?","tier - 2",L8) -> tier - 1 | L8: tier - 1 | M8: =IF(N8="?","tier - 1",N8) -> tier - 3 | N8: tier - 3 | O8: =IF(P8="?","UNKNOWN",P8) -> R1013 | P8: R1013
A9: Id10 | B9: =SUBSTITUTE(C9,"?",ROUNDUP(AVERAGEIF(C:C,"<>~?",C:C),0)) -> 1978 | C9: 1978 | D9: =SUBSTITUTE(E9,"?","sep") -> Dec | E9: Dec | F9: 29 | G9: =CONCATENATE(F9,"-",D9,"-",B9) -> 29-Dec-1978 | H9: =DATEDIF(G9,DATE(2023,6,8),"Y") -> 44 | I9: 0 | J9: 48885.14 | K9: =IF(L9="?","tier - 2",L9) -> tier - 1 | L9: tier - 1 | M9: =IF(N9="?","tier - 1",N9) -> tier - 2 | N9: tier - 2 | O9: =IF(P9="?","UNKNOWN",P9) -> R1013 | P9: R1013
A10: Id100 | B10: =SUBSTITUTE(C10,"?",ROUNDUP(AVERAGEIF(C:C,"<>~?",C:C),0)) -> 1977 | C10: 1977 | D10: =SUBSTITUTE(E10,"?","sep") -> Jun | E10: Jun | F10: 27 | G10: =CONCATENATE(F10,"-",D10,"-",B10) -> 27-Jun-1977 | H10: =DATEDIF(G10,DATE(2023,6,8),"Y") -> 45 | I10: 2 | J10: 40284.38 | K10: =IF(L10="?","tier - 2",L10) -> tier - 1 | L10: tier - 1 | M10: =IF(N10="?","tier - 1",N10) -> tier - 3 | N10: tier - 3 | O10: =IF(P10="?","UNKNOWN",P10) -> R1012 | P10: R1012
A11: Id1000 | B11: =SUBSTITUTE(C11,"?",ROUNDUP(AVERAGEIF(C:C,"<>~?",C:C),0)) -> 1989 | C11: 1989 | D11: =SUBSTITUTE(E11,"?","sep") -> Dec | E11: Dec | F11: 17 | G11: =CONCATENATE(F11,"-",D11,"-",B11) -> 17-Dec-1989 | H11: =DATEDIF(G11,DATE(2023,6,8),"Y") -> 33 | I11: 3 | J11: 11250.43 | K11: =IF(L11="?","tier - 2",L11) -> tier - 3 | L11: tier - 3 | M11: =IF(N11="?","tier - 1",N11) -> tier - 2 | N11: tier - 2 | O11: =IF(P11="?","UNKNOWN",P11) -> R1026 | P11: R1026
A12: Id1001 | B12: =SUBSTITUTE(C12,"?",ROUNDUP(AVERAGEIF(C:C,"<>~?",C:C),0)) -> 1969 | C12: 1969 | D12: =SUBSTITUTE(E12,"?","sep") -> Dec | E12: Dec | F12: 30 | G12: =CONCATENATE(F12,"-",D12,"-",B12) -> 30-Dec-1969 | H12: =DATEDIF(G12,DATE(2023,6,8),"Y") -> 53 | I12: 2 | J12: 11244.38 | K12: =IF(L12="?","tier - 2",L12) -> tier - 3 | L12: tier - 3 | M12: =IF(N12="?","tier - 1",N12) -> tier - 1 | N12: tier - 1 | O12: =IF(P12="?","UNKNOWN",P12) -> R1016 | P12: R1016
A13: Id1002 | B13: =SUBSTITUTE(C13,"?",ROUNDUP(AVERAGEIF(C:C,"<>~?",C:C),0)) -> 1976 | C13: 1976 | D13: =SUBSTITUTE(E13,"?","sep") -> Jun | E13: Jun | F13: 28 | G13: =CONCATENATE(F13,"-",D13,"-",B13) -> 28-Jun-1976 | H13: =DATEDIF(G13,DATE(2023,6,8),"Y") -> 46 | I13: 2 | J13: 11217.35 | K13: =IF(L13="?","tier - 2",L13) -> tier - 3 | L13: tier - 3 | M13: =IF(N13="?","tier - 1",N13) -> tier - 2 | N13: tier - 2 | O13: =IF(P13="?","UNKNOWN",P13) -> R1025 | P13: R1025
... A326: Id1285 | B326: =SUBSTITUTE(C326,"?",ROUNDUP(AVERAGEIF(C:C,"<>~?",C:C),0)) -> 1975 | C326: 1975 | D326: =SUBSTITUTE(E326,"?","sep") -> Aug | E326: Aug | F326: 6 | G326: =CONCATENATE(F326,"-",D326,"-",B326) -> 6-Aug-1975 | H326: =DATEDIF(G326,DATE(2023,6,8),"Y") -> 47 | I326: 1 | J326: 8551.35 | K326: =IF(L326="?","tier - 2",L326) -> tier - 2 | L326: tier - 2 | M326: =IF(N326="?","tier - 1",N326) -> tier - 2 | N326: tier - 2 | O326: =IF(P326="?","UNKNOWN",P326) -> R1011 | P326: R1011
A327: Id1286 | B327: =SUBSTITUTE(C327,"?",ROUNDUP(AVERAGEIF(C:C,"<>~?",C:C),0)) -> 1983 | C327: ? | D327: =SUBSTITUTE(E327,"?","sep") -> Dec | E327: Dec | F327: 12 | G327: =CONCATENATE(F327,"-",D327,"-",B327) -> 12-Dec-1983 | H327: =DATEDIF(G327,DATE(2023,6,8),"Y") -> 39 | I327: 1 | J327: 8547.69 | K327: =IF(L327="?","tier - 2",L327) -> tier - 2 | L327: tier - 2 | M327: =IF(N327="?","tier - 1",N327) -> tier - 1 | N327: tier - 1 | O327: =IF(P327="?","UNKNOWN",P327) -> R1013 | P327: R1013
A328: Id1287 | B328: =SUBSTITUTE(C328,"?",ROUNDUP(AVERAGEIF(C:C,"<>~?",C:C),0)) -> 1975 | C328: 1975 | D328: =SUBSTITUTE(E328,"?","sep") -> Nov | E328: Nov | F328: 6 | G328: =CONCATENATE(F328,"-",D328,"-",B328) -> 6-Nov-1975 | H328: =DATEDIF(G328,DATE(2023,6,8),"Y") -> 47 | I328: 1 | J328: 8539.67 | K328: =IF(L328="?","tier - 2",L328) -> tier - 2 | L328: tier - 2 | M328: =IF(N328="?","tier - 1",N328) -> tier - 3 | N328: tier - 3 | O328: =IF(P328="?","UNKNOWN",P328) -> R1011 | P328: R1011
A329: Id1288 | B329: =SUBSTITUTE(C329,"?",ROUNDUP(AVERAGEIF(C:C,"<>~?",C:C),0)) -> 1981 | C329: 1981 | D329: =SUBSTITUTE(E329,"?","sep") -> Dec | E329: Dec | F329: 27 | G329: =CONCATENATE(F329,"-",D329,"-",B329) -> 27-Dec-1981 | H329: =DATEDIF(G329,DATE(2023,6,8),"Y") -> 41 | I329: 3 | J329: 8538.29 | K329: =IF(L329="?","tier - 2",L329) -> tier - 2 | L329: tier - 2 | M329: =IF(N329="?","tier - 1",N329) -> tier - 3 | N329: tier - 3 | O329: =IF(P329="?","UNKNOWN",P329) -> R1024 | P329: R1024
A330: Id1289 | B330: =SUBSTITUTE(C330,"?",ROUNDUP(AVERAGEIF(C:C,"<>~?",C:C),0)) -> 1983 | C330: ? | D330: =SUBSTITUTE(E330,"?","sep") -> Jul | E330: Jul | F330: 24 | G330: =CONCATENATE(F330,"-",D330,"-",B330) -> 24-Jul-1983 | H330: =DATEDIF(G330,DATE(2023,6,8),"Y") -> 39 | I330: 0 | J330: 8534.67 | K330: =IF(L330="?","tier - 2",L330) -> tier - 2 | L330: tier - 2 | M330: =IF(N330="?","tier - 1",N330) -> tier - 3 | N330: tier - 3 | O330: =IF(P330="?","UNKNOWN",P330) -> R1024 | P330: R1024
A331: Id129 | B331: =SUBSTITUTE(C331,"?",ROUNDUP(AVERAGEIF(C:C,"<>~?",C:C),0)) -> 1985 | C331: 1985 | D331: =SUBSTITUTE(E331,"?","sep") -> Sep | E331: Sep | F331: 20 | G331: =CONCATENATE(F331,"-",D331,"-",B331) -> 20-Sep-1985 | H331: =DATEDIF(G331,DATE(2023,6,8),"Y") -> 37 | I331: 1 | J331: 39047.29 | K331: =IF(L331="?","tier - 2",L331) -> tier - 1 | L331: tier - 1 | M331: =IF(N331="?","tier - 1",N331) -> tier - 3 | N331: tier - 3 | O331: =IF(P331="?","UNKNOWN",P331) -> R1017 | P331: R1017
A332: Id1290 | B332: =SUBSTITUTE(C332,"?",ROUNDUP(AVERAGEIF(C:C,"<>~?",C:C),0)) -> 1977 | C332: 1977 | D332: =SUBSTITUTE(E332,"?","sep") -> Jul | E332: Jul | F332: 26 | G332: =CONCATENATE(F332,"-",D332,"-",B332) -> 26-Jul-1977 | H332: =DATEDIF(G332,DATE(2023,6,8),"Y") -> 45 | I332: 2 | J332: 8527.53 | K332: =IF(L332="?","tier - 2",L332) -> tier - 2 | L332: tier - 2 | M332: =IF(N332="?","tier - 1",N332) -> tier - 2 | N332: tier - 2 | O332: =IF(P332="?","UNKNOWN",P332) -> R1013 | P332: R1013
A333: Id1291 | B333: =SUBSTITUTE(C333,"?",ROUNDUP(AVERAGEIF(C:C,"<>~?",C:C),0)) -> 1979 | C333: 1979 | D333: =SUBSTITUTE(E333,"?","sep") -> Aug | E333: Aug | F333: 13 | G333: =CONCATENATE(F333,"-",D333,"-",B333) -> 13-Aug-1979 | H333: =DATEDIF(G333,DATE(2023,6,8),"Y") -> 43 | I333: 3 | J333: 8522 | K333: =IF(L333="?","tier - 2",L333) -> tier - 2 | L333: tier - 2 | M333: =IF(N333="?","tier - 1",N333) -> tier - 2 | N333: tier - 2 | O333: =IF(P333="?","UNKNOWN",P333) -> R1011 | P333: R1011
A334: Id1292 | B334: =SUBSTITUTE(C334,"?",ROUNDUP(AVERAGEIF(C:C,"<>~?",C:C),0)) -> 1977 | C334: 1977 | D334: =SUBSTITUTE(E334,"?","sep") -> Dec | E334: Dec | F334: 29 | G334: =CONCATENATE(F334,"-",D334,"-",B334) -> 29-Dec-1977 | H334: =DATEDIF(G334,DATE(2023,6,8),"Y") -> 45 | I334: 2 | J334: 8520.03 | K334: =IF(L334="?","tier - 2",L334) -> tier - 2 | L334: tier - 2 | M334: =IF(N334="?","tier - 1",N334) -> tier - 3 | N334: tier - 3 | O334: =IF(P334="?","UNKNOWN",P334) -> R1011 | P334: R1011
A335: Id1293 | B335: =SUBSTITUTE(C335,"?",ROUNDUP(AVERAGEIF(C:C,"<>~?",C:C),0)) -> 1977 | C335: 1977 | D335: =SUBSTITUTE(E335,"?","sep") -> Jun | E335: Jun | F335: 21 | G335: =CONCATENATE(F335,"-",D335,"-",B335) -> 21-Jun-1977 | H335: =DATEDIF(G335,DATE(2023,6,8),"Y") -> 45 | I335: 2 | J335: 8516.83 | K335: =IF(L335="?","tier - 2",L335) -> tier - 2 | L335: tier - 2 | M335: =IF(N335="?","tier - 1",N335) -> tier - 1 | N335: tier - 1 | O335: =IF(P335="?","UNKNOWN",P335) -> R1013 | P335: R1013
A336: Id1294 | B336: =SUBSTITUTE(C336,"?",ROUNDUP(AVERAGEIF(C:C,"<>~?",C:C),0)) -> 1977 | C336: 1977 | D336: =SUBSTITUTE(E336,"?","sep") -> Dec | E336: Dec | F336: 26 | G336: =CONCATENATE(F336,"-",D336,"-",B336) -> 26-Dec-1977 | H336: =DATEDIF(G336,DATE(2023,6,8),"Y") -> 45 | I336: 2 | J336: 8515.76 | K336: =IF(L336="?","tier - 2",L336) -> tier - 2 | L336: tier - 2 | M336: =IF(N336="?","tier - 1",N336) -> tier - 2 | N336: tier - 2 | O336: =IF(P336="?","UNKNOWN",P336) -> R1013 | P336: R1013
A337: Id1295 | B337: =SUBSTITUTE(C337,"?",ROUNDUP(AVERAGEIF(C:C,"<>~?",C:C),0)) -> 1993 | C337: 1993 | D337: =SUBSTITUTE(E337,"?","sep") -> Nov | E337: Nov | F337: 10 | G337: =CONCATENATE(F337,"-",D337,"-",B337) -> 10-Nov-1993 | H337: =DATEDIF(G337,DATE(2023,6,8),"Y") -> 29 | I337: 0 | J337: 8471.65 | K337: =IF(L337="?","tier - 2",L337) -> tier - 2 | L337: tier - 2 | M337: =IF(N337="?","tier - 1",N337) -> tier - 1 | N337: tier - 1 | O337: =IF(P337="?","UNKNOWN",P337) -> R1012 | P337: R1012
A338: Id1296 | B338: =SUBSTITUTE(C338,"?",ROUNDUP(AVERAGEIF(C:C,"<>~?",C:C),0)) -> 1992 | C338: 1992 | D338: =SUBSTITUTE(E338,"?","sep") -> Sep | E338: Sep | F338: 9 | G338: =CONCATENATE(F338,"-",D338,"-",B338) -> 9-Sep-1992 | H338: =DATEDIF(G338,DATE(2023,6,8),"Y") -> 30 | I338: 0 | J338: 8466.35 | K338: =IF(L338="?","tier - 2",L338) -> tier - 2 | L338: tier - 2 | M338: =IF(N338="?","tier - 1",N338) -> tier - 2 | N338: tier - 2 | O338: =IF(P338="?","UNKNOWN",P338) -> R1012 | P338: R1012
A339: Id1297 | B339: =SUBSTITUTE(C339,"?",ROUNDUP(AVERAGEIF(C:C,"<>~?",C:C),0)) -> 1972 | C339: 1972 | D339: =SUBSTITUTE(E339,"?","sep") -> Dec | E339: Dec | F339: 26 | G339: =CONCATENATE(F339,"-",D339,"-",B339) -> 26-Dec-1972 | H339: =DATEDIF(G339,DATE(2023,6,8),"Y") -> 50 | I339: 0 | J339: 8457.82 | K339: =IF(L339="?","tier - 2",L339) -> tier - 2 | L339: tier - 2 | M339: =IF(N339="?","tier - 1",N339) -> tier - 3 | N339: tier - 3 | O339: =IF(P339="?","UNKNOWN",P339) -> R1011 | P339: R1011
A340: Id1298 | B340: =SUBSTITUTE(C340,"?",ROUNDUP(AVERAGEIF(C:C,"<>~?",C:C),0)) -> 1984 | C340: 1984 | D340: =SUBSTITUTE(E340,"?","sep") -> Jun | E340: Jun | F340: 19 | G340: =CONCATENATE(F340,"-",D340,"-",B340) -> 19-Jun-1984 | H340: =DATEDIF(G340,DATE(2023,6,8),"Y") -> 38 | I340: 3 | J340: 8450.82 | K340: =IF(L340="?","tier - 2",L340) -> tier - 2 | L340: tier - 2 | M340: =IF(N340="?","tier - 1",N340) -> tier - 2 | N340: tier - 2 | O340: =IF(P340="?","UNKNOWN",P340) -> R1025 | P340: R1025
A341: Id1299 | B341: =SUBSTITUTE(C341,"?",ROUNDUP(AVERAGEIF(C:C,"<>~?",C:C),0)) -> 1966 | C341: 1966 | D341: =SUBSTITUTE(E341,"?","sep") -> Jun | E341: Jun | F341: 12 | G341: =CONCATENATE(F341,"-",D341,"-",B341) -> 12-Jun-1966 | H341: =DATEDIF(G341,DATE(2023,6,8),"Y") -> 56 | I341: 0 | J341: 8448.66 | K341: =IF(L341="?","tier - 2",L341) -> tier - 3 | L341: tier - 3 | M341: =IF(N341="?","tier - 1",N341) -> tier - 1 | N341: tier - 1 | O341: =IF(P341="?","UNKNOWN",P341) -> R1013 | P341: R1013
A342: Id13 | B342: =SUBSTITUTE(C342,"?",ROUNDUP(AVERAGEIF(C:C,"<>~?",C:C),0)) -> 1962 | C342: 1962 | D342: =SUBSTITUTE(E342,"?","sep") -> Oct | E342: Oct | F342: 11 | G342: =CONCATENATE(F342,"-",D342,"-",B342) -> 11-Oct-1962 | H342: =DATEDIF(G342,DATE(2023,6,8),"Y") -> 60 | I342: 0 | J342: 48673.56 | K342: =IF(L342="?","tier - 2",L342) -> tier - 1 | L342: tier - 1 | M342: =IF(N342="?","tier - 1",N342) -> tier - 2 | N342: tier - 2 | O342: =IF(P342="?","UNKNOWN",P342) -> R1013 | P342: R1013
... A1492: Id2334 | B1492: =SUBSTITUTE(C1492,"?",ROUNDUP(AVERAGEIF(C:C,"<>~?",C:C),0)) -> 1992 | C1492: 1992 | D1492: =SUBSTITUTE(E1492,"?","sep") -> Nov | E1492: Nov | F1492: 30 | G1492: =CONCATENATE(F1492,"-",D1492,"-",B1492) -> 30-Nov-1992 | H1492: =DATEDIF(G1492,DATE(2023,6,8),"Y") -> 30 | I1492: 0 | J1492: 570.62 | K1492: =IF(L1492="?","tier - 2",L1492) -> tier - 2 | L1492: tier - 2 | M1492: =IF(N1492="?","tier - 1",N1492) -> tier - 1 | N1492: tier - 1 | O1492: =IF(P1492="?","UNKNOWN",P1492) -> R1013 | P1492: R1013
A1493: Id2335 | B1493: =SUBSTITUTE(C1493,"?",ROUNDUP(AVERAGEIF(C:C,"<>~?",C:C),0)) -> 1992 | C1493: 1992 | D1493: =SUBSTITUTE(E1493,"?","sep") -> Jul | E1493: Jul | F1493: 9 | G1493: =CONCATENATE(F1493,"-",D1493,"-",B1493) -> 9-Jul-1992 | H1493: =DATEDIF(G1493,DATE(2023,6,8),"Y") -> 30 | I1493: 0 | J1493: 563.84 | K1493: =IF(L1493="?","tier - 2",L1493) -> tier - 2 | L1493: tier - 2 | M1493: =IF(N1493="?","tier - 1",N1493) -> tier - 3 | N1493: tier - 3 | O1493: =IF(P1493="?","UNKNOWN",P1493) -> R1013 | P1493: R1013 | Q1493: =COUNTIF(A1492:P3835,"?") -> 1
A1494: Id234 | B1494: =SUBSTITUTE(C1494,"?",ROUNDUP(AVERAGEIF(C:C,"<>~?",C:C),0)) -> 1994 | C1494: 1994 | D1494: =SUBSTITUTE(E1494,"?","sep") -> Jul | E1494: Jul | F1494: 7 | G1494: =CONCATENATE(F1494,"-",D1494,"-",B1494) -> 7-Jul-1994 | H1494: =DATEDIF(G1494,DATE(2023,6,8),"Y") -> 28 | I1494: 0 | J1494: 34672.15 | K1494: =IF(L1494="?","tier - 2",L1494) -> tier - 1 | L1494: tier - 1 | M1494: =IF(N1494="?","tier - 1",N1494) -> tier - 3 | N1494: tier - 3 | O1494: =IF(P1494="?","UNKNOWN",P1494) -> R1013 | P1494: R1013
A1495: Id235 | B1495: =SUBSTITUTE(C1495,"?",ROUNDUP(AVERAGEIF(C:C,"<>~?",C:C),0)) -> 2004 | C1495: 2004 | D1495: =SUBSTITUTE(E1495,"?","sep") -> Oct | E1495: Oct | F1495: 9 | G1495: =CONCATENATE(F1495,"-",D1495,"-",B1495) -> 9-Oct-2004 | H1495: =DATEDIF(G1495,DATE(2023,6,8),"Y") -> 18 | I1495: 0 | J1495: 34617.84 | K1495: =IF(L1495="?","tier - 2",L1495) -> tier - 1 | L1495: tier - 1 | M1495: =IF(N1495="?","tier - 1",N1495) -> tier - 3 | N1495: tier - 3 | O1495: =IF(P1495="?","UNKNOWN",P1495) -> R1016 | P1495: R1016
A1496: Id236 | B1496: =SUBSTITUTE(C1496,"?",ROUNDUP(AVERAGEIF(C:C,"<>~?",C:C),0)) -> 1976 | C1496: 1976 | D1496: =SUBSTITUTE(E1496,"?","sep") -> Nov | E1496: Nov | F1496: 25 | G1496: =CONCATENATE(F1496,"-",D1496,"-",B1496) -> 25-Nov-1976 | H1496: =DATEDIF(G1496,DATE(2023,6,8),"Y") -> 46 | I1496: 2 | J1496: 34543.39 | K1496: =IF(L1496="?","tier - 2",L1496) -> tier - 2 | L1496: tier - 2 | M1496: =IF(N1496="?","tier - 1",N1496) -> tier - 3 | N1496: tier - 3 | O1496: =IF(P1496="?","UNKNOWN",P1496) -> R1011 | P1496: R1011
A1497: Id237 | B1497: =SUBSTITUTE(C1497,"?",ROUNDUP(AVERAGEIF(C:C,"<>~?",C:C),0)) -> 1998 | C1497: 1998 | D1497: =SUBSTITUTE(E1497,"?","sep") -> Jun | E1497: Jun | F1497: 24 | G1497: =CONCATENATE(F1497,"-",D1497,"-",B1497) -> 24-Jun-1998 | H1497: =DATEDIF(G1497,DATE(2023,6,8),"Y") -> 24 | I1497: 0 | J1497: 34472.84 | K1497: =IF(L1497="?","tier - 2",L1497) -> tier - 1 | L1497: tier - 1 | M1497: =IF(N1497="?","tier - 1",N1497) -> tier - 3 | N1497: tier - 3 | O1497: =IF(P1497="?","UNKNOWN",P1497) -> R1011 | P1497: R1011
A1498: Id238 | B1498: =SUBSTITUTE(C1498,"?",ROUNDUP(AVERAGEIF(C:C,"<>~?",C:C),0)) -> 1990 | C1498: 1990 | D1498: =SUBSTITUTE(E1498,"?","sep") -> Sep | E1498: Sep | F1498: 24 | G1498: =CONCATENATE(F1498,"-",D1498,"-",B1498) -> 24-Sep-1990 | H1498: =DATEDIF(G1498,DATE(2023,6,8),"Y") -> 32 | I1498: 3 | J1498: 34456.27 | K1498: =IF(L1498="?","tier - 2",L1498) -> tier - 1 | L1498: tier - 1 | M1498: =IF(N1498="?","tier - 1",N1498) -> tier - 2 | N1498: tier - 2 | O1498: =IF(P1498="?","UNKNOWN",P1498) -> R1011 | P1498: R1011
A1499: Id239 | B1499: =SUBSTITUTE(C1499,"?",ROUNDUP(AVERAGEIF(C:C,"<>~?",C:C),0)) -> 2003 | C1499: 2003 | D1499: =SUBSTITUTE(E1499,"?","sep") -> Oct | E1499: Oct | F1499: 5 | G1499: =CONCATENATE(F1499,"-",D1499,"-",B1499) -> 5-Oct-2003 | H1499: =DATEDIF(G1499,DATE(2023,6,8),"Y") -> 19 | I1499: 0 | J1499: 34439.86 | K1499: =IF(L1499="?","tier - 2",L1499) -> tier - 2 | L1499: tier - 2 | M1499: =IF(N1499="?","tier - 1",N1499) -> tier - 1 | N1499: tier - 1 | O1499: =IF(P1499="?","UNKNOWN",P1499) -> R1013 | P1499: R1013
A1500: Id24 | B1500: =SUBSTITUTE(C1500,"?",ROUNDUP(AVERAGEIF(C:C,"<>~?",C:C),0)) -> 1970 | C1500: 1970 | D1500: =SUBSTITUTE(E1500,"?","sep") -> Dec | E1500: Dec | F1500: 28 | G1500: =CONCATENATE(F1500,"-",D1500,"-",B1500) -> 28-Dec-1970 | H1500: =DATEDIF(G1500,DATE(2023,6,8),"Y") -> 52 | I1500: 2 | J1500: 47269.85 | K1500: =IF(L1500="?","tier - 2",L1500) -> tier - 1 | L1500: tier - 1 | M1500: =IF(N1500="?","tier - 1",N1500) -> tier - 2 | N1500: tier - 2 | O1500: =IF(P1500="?","UNKNOWN",P1500) -> R1013 | P1500: R1013
A1501: Id240 | B1501: =SUBSTITUTE(C1501,"?",ROUNDUP(AVERAGEIF(C:C,"<>~?",C:C),0)) -> 1984 | C1501: 1984 | D1501: =SUBSTITUTE(E1501,"?","sep") -> Oct | E1501: Oct | F1501: 1 | G1501: =CONCATENATE(F1501,"-",D1501,"-",B1501) -> 1-Oct-1984 | H1501: =DATEDIF(G1501,DATE(2023,6,8),"Y") -> 38 | I1501: 3 | J1501: 34402.22 | K1501: =IF(L1501="?","tier - 2",L1501) -> tier - 2 | L1501: tier - 2 | M1501: =IF(N1501="?","tier - 1",N1501) -> tier - 3 | N1501: tier - 3 | O1501: =IF(P1501="?","UNKNOWN",P1501) -> R1011 | P1501: R1011
...

Sheet Health Care
A1: Customer ID | B1: First Name | C1: BMI | D1: HBA1C | E1: Heart Issues | F1: Any Transplants | G1: Cancer history | H1: Number Of Major Surgeries | I1: Smoker | J1: Weight Status | K1: Diabetes Status | L1: Date of Birth | M1: Charges | N1: Hospital tier | O1: City tier | P1: State ID | Q1: Age
A2: ='Customer Names'!A2 -> Id1 | B2: =IFERROR(VLOOKUP($A2,'Customer Names'!$A:$F,3,FALSE),"") -> Hawks | C2: =IFERROR(VLOOKUP($A2,'Medical Examinations'!$A:$O,2,FALSE),"") -> 47.41 | D2: =IFERROR(VLOOKUP($A2,'Medical Examinations'!$A:$O,3,FALSE),"") -> 7.47 | E2: =IFERROR(VLOOKUP($A2,'Medical Examinations'!$A:$O,4,FALSE),"") -> No | F2: =IFERROR(VLOOKUP($A2,'Medical Examinations'!$A:$O,6,FALSE),"") -> No | G2: =IFERROR(VLOOKUP($A2,'Medical Examinations'!$A:$O,7,FALSE),"") -> No | H2: =IFERROR(VLOOKUP($A2,'Medical Examinations'!$A:$O,8,FALSE),"") -> 0 | I2: =IFERROR(VLOOKUP($A2,'Medical Examinations'!$A:$O,10,FALSE),"") -> Yes | J2: =IFERROR(VLOOKUP($A2,'Medical Examinations'!$A:$O,14,FALSE),"") -> Obesity | K2: =IFERROR(VLOOKUP($A2,'Medical Examinations'!$A:$O,15,FALSE),"") -> Diabetes | L2: =IFERROR(VLOOKUP($A2,'Hospitalisation Details'!$A:$Q,7,FALSE),"") -> 12-Oct-1968 | M2: =IFERROR(VLOOKUP($A2,'Hospitalisation Details'!$A:$Q,10,FALSE),"") -> 63770.43 | N2: =IFERROR(VLOOKUP($A2,'Hospitalisation Details'!$A:$Q,11,FALSE),"") -> tier - 1 | O2: =IFERROR(VLOOKUP($A2,'Hospitalisation Details'!$A:$Q,13,FALSE),"") -> tier - 3 | P2: =IFERROR(VLOOKUP($A2,'Hospitalisation Details'!$A:$Q,15,FALSE),"") -> R1013 | Q2: =IFERROR(VLOOKUP($A2,'Hospitalisation Details'!$A:$Q,8,FALSE),"") -> 54
A3: ='Customer Names'!A11 -> Id10 | B3: =IFERROR(VLOOKUP($A3,'Customer Names'!$A:$F,3,FALSE),"") -> Benner | C3: =IFERROR(VLOOKUP($A3,'Medical Examinations'!$A:$O,2,FALSE),"") -> 38.06 | D3: =IFERROR(VLOOKUP($A3,'Medical Examinations'!$A:$O,3,FALSE),"") -> 10.79 | E3: =IFERROR(VLOOKUP($A3,'Medical Examinations'!$A:$O,4,FALSE),"") -> No | F3: =IFERROR(VLOOKUP($A3,'Medical Examinations'!$A:$O,6,FALSE),"") -> No | G3: =IFERROR(VLOOKUP($A3,'Medical Examinations'!$A:$O,7,FALSE),"") -> No | H3: =IFERROR(VLOOKUP($A3,'Medical Examinations'!$A:$O,8,FALSE),"") -> 0 | I3: =IFERROR(VLOOKUP($A3,'Medical Examinations'!$A:$O,10,FALSE),"") -> Yes | J3: =IFERROR(VLOOKUP($A3,'Medical Examinations'!$A:$O,14,FALSE),"") -> Obesity | K3: =IFERROR(VLOOKUP($A3,'Medical Examinations'!$A:$O,15,FALSE),"") -> Diabetes | L3: =IFERROR(VLOOKUP($A3,'Hospitalisation Details'!$A:$Q,7,FALSE),"") -> 29-Dec-1978 | M3: =IFERROR(VLOOKUP($A3,'Hospitalisation Details'!$A:$Q,10,FALSE),"") -> 48885.14 | N3: =IFERROR(VLOOKUP($A3,'Hospitalisation Details'!$A:$Q,11,FALSE),"") -> tier - 1 | O3: =IFERROR(VLOOKUP($A3,'Hospitalisation Details'!$A:$Q,13,FALSE),"") -> tier - 2 | P3: =IFERROR(VLOOKUP($A3,'Hospitalisation Details'!$A:$Q,15,FALSE),"") -> R1013 | Q3: =IFERROR(VLOOKUP($A3,'Hospitalisation Details'!$A:$Q,8,FALSE),"") -> 44
A4: ='Customer Names'!A101 -> Id100 | B4: =IFERROR(VLOOKUP($A4,'Customer Names'!$A:$F,3,FALSE),"") -> Gollins | C4: =IFERROR(VLOOKUP($A4,'Medical Examinations'!$A:$O,2,FALSE),"") -> 48.2 | D4: =IFERROR(VLOOKUP($A4,'Medical Examinations'!$A:$O,3,FALSE),"") -> 4.84 | E4: =IFERROR(VLOOKUP($A4,'Medical Examinations'!$A:$O,4,FALSE),"") -> No | F4: =IFERROR(VLOOKUP($A4,'Medical Examinations'!$A:$O,6,FALSE),"") -> No | G4: =IFERROR(VLOOKUP($A4,'Medical Examinations'!$A:$O,7,FALSE),"") -> No | H4: =IFERROR(VLOOKUP($A4,'Medical Examinations'!$A:$O,8,FALSE),"") -> 0 | I4: =IFERROR(VLOOKUP($A4,'Medical Examinations'!$A:$O,10,FALSE),"") -> Yes | J4: =IFERROR(VLOOKUP($A4,'Medical Examinations'!$A:$O,14,FALSE),"") -> Obesity | K4: =IFERROR(VLOOKUP($A4,'Medical Examinations'!$A:$O,15,FALSE),"") -> Normal | L4: =IFERROR(VLOOKUP($A4,'Hospitalisation Details'!$A:$Q,7,FALSE),"") -> 27-Jun-1977 | M4: =IFERROR(VLOOKUP($A4,'Hospitalisation Details'!$A:$Q,10,FALSE),"") -> 40284.38 | N4: =IFERROR(VLOOKUP($A4,'Hospitalisation Details'!$A:$Q,11,FALSE),"") -> tier - 1 | O4: =IFERROR(VLOOKUP($A4,'Hospitalisation Details'!$A:$Q,13,FALSE),"") -> tier - 3 | P4: =IFERROR(VLOOKUP($A4,'Hospitalisation Details'!$A:$Q,15,FALSE),"") -> R1012 | Q4: =IFERROR(VLOOKUP($A4,'Hospitalisation Details'!$A:$Q,8,FALSE),"") -> 45
A5: ='Customer Names'!A1001 -> Id1000 | B5: =IFERROR(VLOOKUP($A5,'Customer Names'!$A:$F,3,FALSE),"") -> Schaefer | C5: =IFERROR(VLOOKUP($A5,'Medical Examinations'!$A:$O,2,FALSE),"") -> 39.17 | D5: =IFERROR(VLOOKUP($A5,'Medical Examinations'!$A:$O,3,FALSE),"") -> 4.15 | E5: =IFERROR(VLOOKUP($A5,'Medical Examinations'!$A:$O,4,FALSE),"") -> No | F5: =IFERROR(VLOOKUP($A5,'Medical Examinations'!$A:$O,6,FALSE),"") -> No | G5: =IFERROR(VLOOKUP($A5,'Medical Examinations'!$A:$O,7,FALSE),"") -> No | H5: =IFERROR(VLOOKUP($A5,'Medical Examinations'!$A:$O,8,FALSE),"") -> 0 | I5: =IFERROR(VLOOKUP($A5,'Medical Examinations'!$A:$O,10,FALSE),"") -> No | J5: =IFERROR(VLOOKUP($A5,'Medical Examinations'!$A:$O,14,FALSE),"") -> Obesity | K5: =IFERROR(VLOOKUP($A5,'Medical Examinations'!$A:$O,15,FALSE),"") -> Normal | L5: =IFERROR(VLOOKUP($A5,'Hospitalisation Details'!$A:$Q,7,FALSE),"") -> 17-Dec-1989 | M5: =IFERROR(VLOOKUP($A5,'Hospitalisation Details'!$A:$Q,10,FALSE),"") -> 11250.43 | N5: =IFERROR(VLOOKUP($A5,'Hospitalisation Details'!$A:$Q,11,FALSE),"") -> tier - 3 | O5: =IFERROR(VLOOKUP($A5,'Hospitalisation Details'!$A:$Q,13,FALSE),"") -> tier - 2 | P5: =IFERROR(VLOOKUP($A5,'Hospitalisation Details'!$A:$Q,15,FALSE),"") -> R1026 | Q5: =IFERROR(VLOOKUP($A5,'Hospitalisation Details'!$A:$Q,8,FALSE),"") -> 33
A6: ='Customer Names'!A1002 -> Id1001 | B6: =IFERROR(VLOOKUP($A6,'Customer Names'!$A:$F,3,FALSE),"") -> D'Alessandro | C6: =IFERROR(VLOOKUP($A6,'Medical Examinations'!$A:$O,2,FALSE),"") -> 26.41 | D6: =IFERROR(VLOOKUP($A6,'Medical Examinations'!$A:$O,3,FALSE),"") -> 5.99 | E6: =IFERROR(VLOOKUP($A6,'Medical Examinations'!$A:$O,4,FALSE),"") -> Yes | F6: =IFERROR(VLOOKUP($A6,'Medical Examinations'!$A:$O,6,FALSE),"") -> No | G6: =IFERROR(VLOOKUP($A6,'Medical Examinations'!$A:$O,7,FALSE),"") -> Yes | H6: =IFERROR(VLOOKUP($A6,'Medical Examinations'!$A:$O,8,FALSE),"") -> 1 | I6: =IFERROR(VLOOKUP($A6,'Medical Examinations'!$A:$O,10,FALSE),"") -> No | J6: =IFERROR(VLOOKUP($A6,'Medical Examinations'!$A:$O,14,FALSE),"") -> Over Weight | K6: =IFERROR(VLOOKUP($A6,'Medical Examinations'!$A:$O,15,FALSE),"") -> Prediabetes | L6: =IFERROR(VLOOKUP($A6,'Hospitalisation Details'!$A:$Q,7,FALSE),"") -> 30-Dec-1969 | M6: =IFERROR(VLOOKUP($A6,'Hospitalisation Details'!$A:$Q,10,FALSE),"") -> 11244.38 | N6: =IFERROR(VLOOKUP($A6,'Hospitalisation Details'!$A:$Q,11,FALSE),"") -> tier - 3 | O6: =IFERROR(VLOOKUP($A6,'Hospitalisation Details'!$A:$Q,13,FALSE),"") -> tier - 1 | P6: =IFERROR(VLOOKUP($A6,'Hospitalisation Details'!$A:$Q,15,FALSE),"") -> R1016 | Q6: =IFERROR(VLOOKUP($A6,'Hospitalisation Details'!$A:$Q,8,FALSE),"") -> 53
A7: ='Customer Names'!A1003 -> Id1002 | B7: =IFERROR(VLOOKUP($A7,'Customer Names'!$A:$F,3,FALSE),"") -> Wyss | C7: =IFERROR(VLOOKUP($A7,'Medical Examinations'!$A:$O,2,FALSE),"") -> 30.63 | D7: =IFERROR(VLOOKUP($A7,'Medical Examinations'!$A:$O,3,FALSE),"") -> 5.8 | E7: =IFERROR(VLOOKUP($A7,'Medical Examinations'!$A:$O,4,FALSE),"") -> Yes | F7: =IFERROR(VLOOKUP($A7,'Medical Examinations'!$A:$O,6,FALSE),"") -> No | G7: =IFERROR(VLOOKUP($A7,'Medical Examinations'!$A:$O,7,FALSE),"") -> No | H7: =IFERROR(VLOOKUP($A7,'Medical Examinations'!$A:$O,8,FALSE),"") -> 0 | I7: =IFERROR(VLOOKUP($A7,'Medical Examinations'!$A:$O,10,FALSE),"") -> No | J7: =IFERROR(VLOOKUP($A7,'Medical Examinations'!$A:$O,14,FALSE),"") -> Obesity | K7: =IFERROR(VLOOKUP($A7,'Medical Examinations'!$A:$O,15,FALSE),"") -> Prediabetes | L7: =IFERROR(VLOOKUP($A7,'Hospitalisation Details'!$A:$Q,7,FALSE),"") -> 28-Jun-1976 | M7: =IFERROR(VLOOKUP($A7,'Hospitalisation Details'!$A:$Q,10,FALSE),"") -> 11217.35 | N7: =IFERROR(VLOOKUP($A7,'Hospitalisation Details'!$A:$Q,11,FALSE),"") -> tier - 3 | O7: =IFERROR(VLOOKUP($A7,'Hospitalisation Details'!$A:$Q,13,FALSE),"") -> tier - 2 | P7: =IFERROR(VLOOKUP($A7,'Hospitalisation Details'!$A:$Q,15,FALSE),"") -> R1025 | Q7: =IFERROR(VLOOKUP($A7,'Hospitalisation Details'!$A:$Q,8,FALSE),"") -> 46
A8: ='Customer Names'!A1004 -> Id1003 | B8: =IFERROR(VLOOKUP($A8,'Customer Names'!$A:$F,3,FALSE),"") -> Rose | C8: =IFERROR(VLOOKUP($A8,'Medical Examinations'!$A:$O,2,FALSE),"") -> 31.73 | D8: =IFERROR(VLOOKUP($A8,'Medical Examinations'!$A:$O,3,FALSE),"") -> 7.32 | E8: =IFERROR(VLOOKUP($A8,'Medical Examinations'!$A:$O,4,FALSE),"") -> Yes | F8: =IFERROR(VLOOKUP($A8,'Medical Examinations'!$A:$O,6,FALSE),"") -> No | G8: =IFERROR(VLOOKUP($A8,'Medical Examinations'!$A:$O,7,FALSE),"") -> No | H8: =IFERROR(VLOOKUP($A8,'Medical Examinations'!$A:$O,8,FALSE),"") -> 2 | I8: =IFERROR(VLOOKUP($A8,'Medical Examinations'!$A:$O,10,FALSE),"") -> No | J8: =IFERROR(VLOOKUP($A8,'Medical Examinations'!$A:$O,14,FALSE),"") -> Obesity | K8: =IFERROR(VLOOKUP($A8,'Medical Examinations'!$A:$O,15,FALSE),"") -> Diabetes | L8: =IFERROR(VLOOKUP($A8,'Hospitalisation Details'!$A:$Q,7,FALSE),"") -> 14-Jun-1970 | M8: =IFERROR(VLOOKUP($A8,'Hospitalisation Details'!$A:$Q,10,FALSE),"") -> 11187.66 | N8: =IFERROR(VLOOKUP($A8,'Hospitalisation Details'!$A:$Q,11,FALSE),"") -> tier - 3 | O8: =IFERROR(VLOOKUP($A8,'Hospitalisation Details'!$A:$Q,13,FALSE),"") -> tier - 2 | P8: =IFERROR(VLOOKUP($A8,'Hospitalisation Details'!$A:$Q,15,FALSE),"") -> R1012 | Q8: =IFERROR(VLOOKUP($A8,'Hospitalisation Details'!$A:$Q,8,FALSE),"") -> 52
A9: ='Customer Names'!A1005 -> Id1004 | B9: =IFERROR(VLOOKUP($A9,'Customer Names'!$A:$F,3,FALSE),"") -> Hopper | C9: =IFERROR(VLOOKUP($A9,'Medical Examinations'!$A:$O,2,FALSE),"") -> 30.7 | D9: =IFERROR(VLOOKUP($A9,'Medical Examinations'!$A:$O,3,FALSE),"") -> 5.16 | E9: =IFERROR(VLOOKUP($A9,'Medical Examinations'!$A:$O,4,FALSE),"") -> No | F9: =IFERROR(VLOOKUP($A9,'Medical Examinations'!$A:$O,6,FALSE),"") -> No | G9: =IFERROR(VLOOKUP($A9,'Medical Examinations'!$A:$O,7,FALSE),"") -> No | H9: =IFERROR(VLOOKUP($A9,'Medical Examinations'!$A:$O,8,FALSE),"") -> 2 | I9: =IFERROR(VLOOKUP($A9,'Medical Examinations'!$A:$O,10,FALSE),"") -> No | J9: =IFERROR(VLOOKUP($A9,'Medical Examinations'!$A:$O,14,FALSE),"") -> Obesity | K9: =IFERROR(VLOOKUP($A9,'Medical Examinations'!$A:$O,15,FALSE),"") -> Normal | L9: =IFERROR(VLOOKUP($A9,'Hospitalisation Details'!$A:$Q,7,FALSE),"") -> 3-Sep-1972 | M9: =IFERROR(VLOOKUP($A9,'Hospitalisation Details'!$A:$Q,10,FALSE),"") -> 11186.2 | N9: =IFERROR(VLOOKUP($A9,'Hospitalisation Details'!$A:$Q,11,FALSE),"") -> tier - 3 | O9: =IFERROR(VLOOKUP($A9,'Hospitalisation Details'!$A:$Q,13,FALSE),"") -> tier - 2 | P9: =IFERROR(VLOOKUP($A9,'Hospitalisation Details'!$A:$Q,15,FALSE),"") -> R1021 | Q9: =IFERROR(VLOOKUP($A9,'Hospitalisation Details'!$A:$Q,8,FALSE),"") -> 50
A10: ='Customer Names'!A1006 -> Id1005 | B10: =IFERROR(VLOOKUP($A10,'Customer Names'!$A:$F,3,FALSE),"") -> Finneran | C10: =IFERROR(VLOOKUP($A10,'Medical Examinations'!$A:$O,2,FALSE),"") -> 25.935 | D10: =IFERROR(VLOOKUP($A10,'Medical Examinations'!$A:$O,3,FALSE),"") -> 5.96 | E10: =IFERROR(VLOOKUP($A10,'Medical Examinations'!$A:$O,4,FALSE),"") -> Yes | F10: =IFERROR(VLOOKUP($A10,'Medical Examinations'!$A:$O,6,FALSE),"") -> No | G10: =IFERROR(VLOOKUP($A10,'Medical Examinations'!$A:$O,7,FALSE),"") -> No | H10: =IFERROR(VLOOKUP($A10,'Medical Examinations'!$A:$O,8,FALSE),"") -> 2 | I10: =IFERROR(VLOOKUP($A10,'Medical Examinations'!$A:$O,10,FALSE),"") -> No | J10: =IFERROR(VLOOKUP($A10,'Medical Examinations'!$A:$O,14,FALSE),"") -> Over Weight | K10: =IFERROR(VLOOKUP($A10,'Medical Examinations'!$A:$O,15,FALSE),"") -> Prediabetes | L10: =IFERROR(VLOOKUP($A10,'Hospitalisation Details'!$A:$Q,7,FALSE),"") -> 6-Aug-1966 | M10: =IFERROR(VLOOKUP($A10,'Hospitalisation Details'!$A:$Q,10,FALSE),"") -> 11165.42 | N10: =IFERROR(VLOOKUP($A10,'Hospitalisation Details'!$A:$Q,11,FALSE),"") -> tier - 3 | O10: =IFERROR(VLOOKUP($A10,'Hospitalisation Details'!$A:$Q,13,FALSE),"") -> tier - 1 | P10: =IFERROR(VLOOKUP($A10,'Hospitalisation Details'!$A:$Q,15,FALSE),"") -> R1016 | Q10: =IFERROR(VLOOKUP($A10,'Hospitalisation Details'!$A:$Q,8,FALSE),"") -> 56
A11: ='Customer Names'!A1007 -> Id1006 | B11: =IFERROR(VLOOKUP($A11,'Customer Names'!$A:$F,3,FALSE),"") -> Basham | C11: =IFERROR(VLOOKUP($A11,'Medical Examinations'!$A:$O,2,FALSE),"") -> 35.9 | D11: =IFERROR(VLOOKUP($A11,'Medical Examinations'!$A:$O,3,FALSE),"") -> 4.85 | E11: =IFERROR(VLOOKUP($A11,'Medical Examinations'!$A:$O,4,FALSE),"") -> Yes | F11: =IFERROR(VLOOKUP($A11,'Medical Examinations'!$A:$O,6,FALSE),"") -> No | G11: =IFERROR(VLOOKUP($A11,'Medical Examinations'!$A:$O,7,FALSE),"") -> Yes | H11: =IFERROR(VLOOKUP($A11,'Medical Examinations'!$A:$O,8,FALSE),"") -> 1 | I11: =IFERROR(VLOOKUP($A11,'Medical Examinations'!$A:$O,10,FALSE),"") -> No | J11: =IFERROR(VLOOKUP($A11,'Medical Examinations'!$A:$O,14,FALSE),"") -> Obesity | K11: =IFERROR(VLOOKUP($A11,'Medical Examinations'!$A:$O,15,FALSE),"") -> Normal | L11: =IFERROR(VLOOKUP($A11,'Hospitalisation Details'!$A:$Q,7,FALSE),"") -> 25-Jun-1969 | M11: =IFERROR(VLOOKUP($A11,'Hospitalisation Details'!$A:$Q,10,FALSE),"") -> 11163.57 | N11: =IFERROR(VLOOKUP($A11,'Hospitalisation Details'!$A:$Q,11,FALSE),"") -> tier - 3 | O11: =IFERROR(VLOOKUP($A11,'Hospitalisation Details'!$A:$Q,13,FALSE),"") -> tier - 2 | P11: =IFERROR(VLOOKUP($A11,'Hospitalisation Details'!$A:$Q,15,FALSE),"") -> R1011 | Q11: =IFERROR(VLOOKUP($A11,'Hospitalisation Details'!$A:$Q,8,FALSE),"") -> 53
A12: ='Customer Names'!A1008 -> Id1007 | B12: =IFERROR(VLOOKUP($A12,'Customer Names'!$A:$F,3,FALSE),"") -> Inman | C12: =IFERROR(VLOOKUP($A12,'Medical Examinations'!$A:$O,2,FALSE),"") -> 26.7 | D12: =IFERROR(VLOOKUP($A12,'Medical Examinations'!$A:$O,3,FALSE),"") -> 5.09 | E12: =IFERROR(VLOOKUP($A12,'Medical Examinations'!$A:$O,4,FALSE),"") -> Yes | F12: =IFERROR(VLOOKUP($A12,'Medical Examinations'!$A:$O,6,FALSE),"") -> No | G12: =IFERROR(VLOOKUP($A12,'Medical Examinations'!$A:$O,7,FALSE),"") -> Yes | H12: =IFERROR(VLOOKUP($A12,'Medical Examinations'!$A:$O,8,FALSE),"") -> 1 | I12: =IFERROR(VLOOKUP($A12,'Medical Examinations'!$A:$O,10,FALSE),"") -> No | J12: =IFERROR(VLOOKUP($A12,'Medical Examinations'!$A:$O,14,FALSE),"") -> Over Weight | K12: =IFERROR(VLOOKUP($A12,'Medical Examinations'!$A:$O,15,FALSE),"") -> Normal | L12: =IFERROR(VLOOKUP($A12,'Hospitalisation Details'!$A:$Q,7,FALSE),"") -> 30-Nov-1969 | M12: =IFERROR(VLOOKUP($A12,'Hospitalisation Details'!$A:$Q,10,FALSE),"") -> 11150.78 | N12: =IFERROR(VLOOKUP($A12,'Hospitalisation Details'!$A:$Q,11,FALSE),"") -> tier - 3 | O12: =IFERROR(VLOOKUP($A12,'Hospitalisation Details'!$A:$Q,13,FALSE),"") -> tier - 2 | P12: =IFERROR(VLOOKUP($A12,'Hospitalisation Details'!$A:$Q,15,FALSE),"") -> R1011 | Q12: =IFERROR(VLOOKUP($A12,'Hospitalisation Details'!$A:$Q,8,FALSE),"") -> 53
A13: ='Customer Names'!A1009 -> Id1008 | B13: =IFERROR(VLOOKUP($A13,'Customer Names'!$A:$F,3,FALSE),"") -> Oscal | C13: =IFERROR(VLOOKUP($A13,'Medical Examinations'!$A:$O,2,FALSE),"") -> 33.71 | D13: =IFERROR(VLOOKUP($A13,'Medical Examinations'!$A:$O,3,FALSE),"") -> 4.94 | E13: =IFERROR(VLOOKUP($A13,'Medical Examinations'!$A:$O,4,FALSE),"") -> No | F13: =IFERROR(VLOOKUP($A13,'Medical Examinations'!$A:$O,6,FALSE),"") -> No | G13: =IFERROR(VLOOKUP($A13,'Medical Examinations'!$A:$O,7,FALSE),"") -> No | H13: =IFERROR(VLOOKUP($A13,'Medical Examinations'!$A:$O,8,FALSE),"") -> 0 | I13: =IFERROR(VLOOKUP($A13,'Medical Examinations'!$A:$O,10,FALSE),"") -> No | J13: =IFERROR(VLOOKUP($A13,'Medical Examinations'!$A:$O,14,FALSE),"") -> Obesity | K13: =IFERROR(VLOOKUP($A13,'Medical Examinations'!$A:$O,15,FALSE),"") -> Normal | L13: =IFERROR(VLOOKUP($A13,'Hospitalisation Details'!$A:$Q,7,FALSE),"") -> 20-Aug-1980 | M13: =IFERROR(VLOOKUP($A13,'Hospitalisation Details'!$A:$Q,10,FALSE),"") -> 11103.33 | N13: =IFERROR(VLOOKUP($A13,'Hospitalisation Details'!$A:$Q,11,FALSE),"") -> tier - 3 | O13: =IFERROR(VLOOKUP($A13,'Hospitalisation Details'!$A:$Q,13,FALSE),"") -> tier - 1 | P13: =IFERROR(VLOOKUP($A13,'Hospitalisation Details'!$A:$Q,15,FALSE),"") -> R1021 | Q13: =IFERROR(VLOOKUP($A13,'Hospitalisation Details'!$A:$Q,8,FALSE),"") -> 42
A14: ='Customer Names'!A1010 -> Id1009 | B14: =IFERROR(VLOOKUP($A14,'Customer Names'!$A:$F,3,FALSE),"") -> Craft | C14: =IFERROR(VLOOKUP($A14,'Medical Examinations'!$A:$O,2,FALSE),"") -> 41.91 | D14: =IFERROR(VLOOKUP($A14,'Medical Examinations'!$A:$O,3,FALSE),"") -> 4.92 | E14: =IFERROR(VLOOKUP($A14,'Medical Examinations'!$A:$O,4,FALSE),"") -> Yes | F14: =IFERROR(VLOOKUP($A14,'Medical Examinations'!$A:$O,6,FALSE),"") -> No | G14: =IFERROR(VLOOKUP($A14,'Medical Examinations'!$A:$O,7,FALSE),"") -> No | H14: =IFERROR(VLOOKUP($A14,'Medical Examinations'!$A:$O,8,FALSE),"") -> 2 | I14: =IFERROR(VLOOKUP($A14,'Medical Examinations'!$A:$O,10,FALSE),"") -> No | J14: =IFERROR(VLOOKUP($A14,'Medical Examinations'!$A:$O,14,FALSE),"") -> Obesity | K14: =IFERROR(VLOOKUP($A14,'Medical Examinations'!$A:$O,15,FALSE),"") -> Normal | L14: =IFERROR(VLOOKUP($A14,'Hospitalisation Details'!$A:$Q,7,FALSE),"") -> 5-Jul-1966 | M14: =IFERROR(VLOOKUP($A14,'Hospitalisation Details'!$A:$Q,10,FALSE),"") -> 11093.62 | N14: =IFERROR(VLOOKUP($A14,'Hospitalisation Details'!$A:$Q,11,FALSE),"") -> tier - 3 | O14: =IFERROR(VLOOKUP($A14,'Hospitalisation Details'!$A:$Q,13,FALSE),"") -> tier - 1 | P14: =IFERROR(VLOOKUP($A14,'Hospitalisation Details'!$A:$Q,15,FALSE),"") -> R1013 | Q14: =IFERROR(VLOOKUP($A14,'Hospitalisation Details'!$A:$Q,8,FALSE),"") -> 56
A15: ='Customer Names'!A102 -> Id101 | B15: =IFERROR(VLOOKUP($A15,'Customer Names'!$A:$F,3,FALSE),"") -> Benestad | C15: =IFERROR(VLOOKUP($A15,'Medical Examinations'!$A:$O,2,FALSE),"") -> 35.75 | D15: =IFERROR(VLOOKUP($A15,'Medical Examinations'!$A:$O,3,FALSE),"") -> 8 | E15: =IFERROR(VLOOKUP($A15,'Medical Examinations'!$A:$O,4,FALSE),"") -> Yes | F15: =IFERROR(VLOOKUP($A15,'Medical Examinations'!$A:$O,6,FALSE),"") -> No | G15: =IFERROR(VLOOKUP($A15,'Medical Examinations'!$A:$O,7,FALSE),"") -> No | H15: =IFERROR(VLOOKUP($A15,'Medical Examinations'!$A:$O,8,FALSE),"") -> 0 | I15: =IFERROR(VLOOKUP($A15,'Medical Examinations'!$A:$O,10,FALSE),"") -> Yes | J15: =IFERROR(VLOOKUP($A15,'Medical Examinations'!$A:$O,14,FALSE),"") -> Obesity | K15: =IFERROR(VLOOKUP($A15,'Medical Examinations'!$A:$O,15,FALSE),"") -> Diabetes | L15: =IFERROR(VLOOKUP($A15,'Hospitalisation Details'!$A:$Q,7,FALSE),"") -> 4-Oct-1981 | M15: =IFERROR(VLOOKUP($A15,'Hospitalisation Details'!$A:$Q,10,FALSE),"") -> 40273.65 | N15: =IFERROR(VLOOKUP($A15,'Hospitalisation Details'!$A:$Q,11,FALSE),"") -> tier - 1 | O15: =IFERROR(VLOOKUP($A15,'Hospitalisation Details'!$A:$Q,13,FALSE),"") -> tier - 3 | P15: =IFERROR(VLOOKUP($A15,'Hospitalisation Details'!$A:$Q,15,FALSE),"") -> R1013 | Q15: =IFERROR(VLOOKUP($A15,'Hospitalisation Details'!$A:$Q,8,FALSE),"") -> 41
